Workbook

Sheet Sheet1
A1: 审批编号 | B1: 客户/项目名称 | C1: 交易合同类型 | D1: 内部类型分类 | E1: 全额部分开票类型 | F1: 不含税金额 | G1: 差额开票金额 | H1: 增值税金额 | I1: 开票总额 | J1: 派遣服务费 | K1: 代理服务费 | L1: 承揽服务费 | M1: 培训收入 | N1: 招聘服务费 | O1: 猎头服务费 | P1: 安心雇收入 | Q1: 小时间承揽服务费 | R1: 内部往来开票 | S1: 代付工资 | T1: 代付个税 | U1: 代付社保 | V1: 代付公积金 | W1: 代付商保 | X1: 代付残保金 | Y1: 代付税金 | Z1: 代付经营费用 | AA1: 代付其他 | AB1: 代付其他政府补贴 | AC1: 租赁转租 | AD1: 总计 | AE1: 总计检验 | AF1: 申请与开票差异 | AG1: 应交增值税 | AH1: 应交城建税 | AI1: 应交教育费附加 | AJ1: 应交地方教育费附加 | AK1: 代付增值税 | AL1: 代付附加税 | AM1: 成本增值税 | AN1: 成本城建税 | AO1: 成本教育费附加 | AP1: 成本地方教育费附加 | AQ1: 辅助列1 | AR1: 辅助2
A2: 202512010914000217639 | B2: 凯辉人才服务（上海）有限公司 | C2: 劳务派遣 | D2: 派遣业务 | E2: 专票（5%） | F2: =ROUND(SUMIF([1]开票!$A$2:$A$1750,[1]申请!AQ2,[1]开票!$C$2:$C$1750),2) -> #VALUE! | G2: =ROUND(SUMIF([1]开票!$A$2:$A$1750,[1]申请!AQ2,[1]开票!$D$2:$D$1750),2) -> 33275 | H2: =ROUND(SUMIF([1]开票!$A$2:$A$1750,[1]申请!AQ2,[1]开票!$E$2:$E$1750),2) -> 11.43 | I2: {=SUM(B3F2:H2)} -> #NAME? | K2: 240 | S2: 20210.4 | T2: 189.6 | U2: 8875 | V2: 4000 | AD2: =SUM(J2:AC2) -> 33515 | AE2: =AD2-SUM(J2:AC2) -> 0 | AF2: =AD2-I2 -> #NAME? | AG2: =ROUND(H2,2) -> 11.43 | AH2: =ROUND(AG2*0.07,2) -> 0.8 | AI2: =ROUND(AG2*0.03,2) -> 0.34 | AJ2: =ROUND(AG2*0.02,2) -> 0.23 | AK2: =IF(AR2,Y2/(AR2*1.12)*AR2,0) -> 0 | AL2: =ROUND(Y2-AK2,2) -> 0 | AM2: =ROUND(AG2-AK2,2) -> 11.43 | AN2: =ROUND(AM2*0.07,2) -> 0.8 | AO2: =ROUND(AM2*0.03,2) -> 0.34 | AP2: =ROUND(AH2+AI2+AJ2-AL2-AN2-AO2,2) -> 0.23 | AQ2: ="TJ"&A2 -> TJ202512010914000217639 | AR2: =IF(E2="无全额",0,MID(E2,4,2)*1) -> 0.05
A3: 202512010936000029991 | B3: 广东-新御运营管理（派遣） | C3: 劳务派遣 | D3: 派遣业务 | E3: 专票（6%） | F3: =ROUND(SUMIF([1]开票!$A$2:$A$1750,[1]申请!AQ3,[1]开票!$C$2:$C$1750),2) -> #VALUE! | G3: =ROUND(SUMIF([1]开票!$A$2:$A$1750,[1]申请!AQ3,[1]开票!$D$2:$D$1750),2) -> 0 | H3: =ROUND(SUMIF([1]开票!$A$2:$A$1750,[1]申请!AQ3,[1]开票!$E$2:$E$1750),2) -> 550.13 | I3: =SUM(F3:H3) -> #VALUE! | J3: 115.19 | Y3: 604.73 | AA3: 8999 | AD3: =SUM(J3:AC3) -> 9718.92 | AE3: =AD3-SUM(J3:AC3) -> 0 | AF3: =AD3-I3 -> #VALUE! | AG3: =ROUND(H3,2) -> 550.13 | AH3: =ROUND(AG3*0.07,2) -> 38.51 | AI3: =ROUND(AG3*0.03,2) -> 16.5 | AJ3: =ROUND(AG3*0.02,2) -> 11 | AK3: =IF(AR3,Y3/(AR3*1.12)*AR3,0) -> 539.9375 | AL3: =ROUND(Y3-AK3,2) -> 64.79 | AM3: =ROUND(AG3-AK3,2) -> 10.19 | AN3: =ROUND(AM3*0.07,2) -> 0.71 | AO3: =ROUND(AM3*0.03,2) -> 0.31 | AP3: =ROUND(AH3+AI3+AJ3-AL3-AN3-AO3,2) -> 0.2 | AQ3: ="TJ"&A3 -> TJ202512010936000029991 | AR3: =IF(E3="无全额",0,MID(E3,4,2)*1) -> 0.06
A4: 202512010952000277009 | B4: 中国中金财富证券有限公司东莞分公司 | C4: 劳务承揽 | D4: 承揽业务 | E4: 专票（6%） | F4: =ROUND(SUMIF([1]开票!$A$2:$A$1750,[1]申请!AQ4,[1]开票!$C$2:$C$1750),2) -> 8773.58 | G4: =ROUND(SUMIF([1]开票!$A$2:$A$1750,[1]申请!AQ4,[1]开票!$D$2:$D$1750),2) -> 0 | H4: =ROUND(SUMIF([1]开票!$A$2:$A$1750,[1]申请!AQ4,[1]开票!$E$2:$E$1750),2) -> 526.42 | I4: =SUM(F4:H4) -> 9300 | L4: 9300 | AD4: =SUM(J4:AC4) -> 9300 | AE4: =AD4-SUM(J4:AC4) -> 0 | AF4: =AD4-I4 -> 0 | AG4: =ROUND(H4,2) -> 526.42 | AH4: =ROUND(AG4*0.07,2) -> 36.85 | AI4: =ROUND(AG4*0.03,2) -> 15.79 | AJ4: =ROUND(AG4*0.02,2) -> 10.53 | AK4: =IF(AR4,Y4/(AR4*1.12)*AR4,0) -> 0 | AL4: =ROUND(Y4-AK4,2) -> 0 | AM4: =ROUND(AG4-AK4,2) -> 526.42 | AN4: =ROUND(AM4*0.07,2) -> 36.85 | AO4: =ROUND(AM4*0.03,2) -> 15.79 | AP4: =ROUND(AH4+AI4+AJ4-AL4-AN4-AO4,2) -> 10.53 | AQ4: ="TJ"&A4 -> TJ202512010952000277009 | AR4: =IF(E4="无全额",0,MID(E4,4,2)*1) -> 0.06
A5: 202512011032000412415 | B5: 蚂蚁HRO | C5: 劳务承揽 | D5: 承揽业务 | E5: 专票（6%） | F5: =ROUND(SUMIF([1]开票!$A$2:$A$1750,[1]申请!AQ5,[1]开票!$C$2:$C$1750),2) -> #VALUE! | G5: =ROUND(SUMIF([1]开票!$A$2:$A$1750,[1]申请!AQ5,[1]开票!$D$2:$D$1750),2) -> 0 | H5: =ROUND(SUMIF([1]开票!$A$2:$A$1750,[1]申请!AQ5,[1]开票!$E$2:$E$1750),2) -> 19285.69 | I5: =SUM(F5:H5) -> #VALUE! | J5: 340713.85 | AD5: =SUM(J5:AC5) -> 340713.85 | AE5: =AD5-SUM(J5:AC5) -> 0 | AF5: =AD5-I5 -> #VALUE! | AG5: =ROUND(H5,2) -> 19285.69 | AH5: =ROUND(AG5*0.07,2) -> 1350 | AI5: =ROUND(AG5*0.03,2) -> 578.57 | AJ5: =ROUND(AG5*0.02,2) -> 385.71 | AK5: =IF(AR5,Y5/(AR5*1.12)*AR5,0) -> 0 | AL5: =ROUND(Y5-AK5,2) -> 0 | AM5: =ROUND(AG5-AK5,2) -> 19285.69 | AN5: =ROUND(AM5*0.07,2) -> 1350 | AO5: =ROUND(AM5*0.03,2) -> 578.57 | AP5: =ROUND(AH5+AI5+AJ5-AL5-AN5-AO5,2) -> 385.71 | AQ5: ="TJ"&A5 -> TJ202512011032000412415 | AR5: =IF(E5="无全额",0,MID(E5,4,2)*1) -> 0.06
A6: 202512011045000017836 | B6: 软通动力信息技术（集团）股份有限公司 | C6: 劳务承揽 | D6: 小时间承揽 | E6: 专票（6%） | F6: =ROUND(SUMIF([1]开票!$A$2:$A$1750,[1]申请!AQ6,[1]开票!$C$2:$C$1750),2) -> 59984.15 | G6: =ROUND(SUMIF([1]开票!$A$2:$A$1750,[1]申请!AQ6,[1]开票!$D$2:$D$1750),2) -> 0 | H6: =ROUND(SUMIF([1]开票!$A$2:$A$1750,[1]申请!AQ6,[1]开票!$E$2:$E$1750),2) -> 3599.05 | I6: =SUM(F6:H6) -> 63583.2 | Q6: 4127.46 | W6: 491.96 | Z6: 58963.78 | AD6: =SUM(J6:AC6) -> 63583.2 | AE6: =AD6-SUM(J6:AC6) -> 0 | AF6: =AD6-I6 -> 0 | AG6: =ROUND(H6,2) -> 3599.05 | AH6: =ROUND(AG6*0.07,2) -> 251.93 | AI6: =ROUND(AG6*0.03,2) -> 107.97 | AJ6: =ROUND(AG6*0.02,2) -> 71.98 | AK6: =IF(AR6,Y6/(AR6*1.12)*AR6,0) -> 0 | AL6: =ROUND(Y6-AK6,2) -> 0 | AM6: =ROUND(AG6-AK6,2) -> 3599.05 | AN6: =ROUND(AM6*0.07,2) -> 251.93 | AO6: =ROUND(AM6*0.03,2) -> 107.97 | AP6: =ROUND(AH6+AI6+AJ6-AL6-AN6-AO6,2) -> 71.98 | AQ6: ="TJ"&A6 -> TJ202512011045000017836 | AR6: =IF(E6="无全额",0,MID(E6,4,2)*1) -> 0.06
A7: 202512011144000382060 | B7: 软通动力信息技术（集团）股份有限公司 | C7: 劳务承揽 | D7: 小时间承揽 | E7: 专票（6%） | F7: =ROUND(SUMIF([1]开票!$A$2:$A$1750,[1]申请!AQ7,[1]开票!$C$2:$C$1750),2) -> 2624.53 | G7: =ROUND(SUMIF([1]开票!$A$2:$A$1750,[1]申请!AQ7,[1]开票!$D$2:$D$1750),2) -> 0 | H7: =ROUND(SUMIF([1]开票!$A$2:$A$1750,[1]申请!AQ7,[1]开票!$E$2:$E$1750),2) -> 157.47 | I7: =SUM(F7:H7) -> 2782 | Q7: 182 | Z7: 2600 | AD7: =SUM(J7:AC7) -> 2782 | AE7: =AD7-SUM(J7:AC7) -> 0 | AF7: =AD7-I7 -> 0 | AG7: =ROUND(H7,2) -> 157.47 | AH7: =ROUND(AG7*0.07,2) -> 11.02 | AI7: =ROUND(AG7*0.03,2) -> 4.72 | AJ7: =ROUND(AG7*0.02,2) -> 3.15 | AK7: =IF(AR7,Y7/(AR7*1.12)*AR7,0) -> 0 | AL7: =ROUND(Y7-AK7,2) -> 0 | AM7: =ROUND(AG7-AK7,2) -> 157.47 | AN7: =ROUND(AM7*0.07,2) -> 11.02 | AO7: =ROUND(AM7*0.03,2) -> 4.72 | AP7: =ROUND(AH7+AI7+AJ7-AL7-AN7-AO7,2) -> 3.15 | AQ7: ="TJ"&A7 -> TJ202512011144000382060 | AR7: =IF(E7="无全额",0,MID(E7,4,2)*1) -> 0.06
A8: 202512011145000566762 | B8: 软通动力信息技术（集团）股份有限公司 | C8: 劳务承揽 | D8: 小时间承揽 | E8: 专票（6%） | F8: =ROUND(SUMIF([1]开票!$A$2:$A$1750,[1]申请!AQ8,[1]开票!$C$2:$C$1750),2) -> 3755.09 | G8: =ROUND(SUMIF([1]开票!$A$2:$A$1750,[1]申请!AQ8,[1]开票!$D$2:$D$1750),2) -> 0 | H8: =ROUND(SUMIF([1]开票!$A$2:$A$1750,[1]申请!AQ8,[1]开票!$E$2:$E$1750),2) -> 225.31 | I8: =SUM(F8:H8) -> 3980.4 | Q8: 260.4 | Z8: 3720 | AD8: =SUM(J8:AC8) -> 3980.4 | AE8: =AD8-SUM(J8:AC8) -> 0 | AF8: =AD8-I8 -> 0 | AG8: =ROUND(H8,2) -> 225.31 | AH8: =ROUND(AG8*0.07,2) -> 15.77 | AI8: =ROUND(AG8*0.03,2) -> 6.76 | AJ8: =ROUND(AG8*0.02,2) -> 4.51 | AK8: =IF(AR8,Y8/(AR8*1.12)*AR8,0) -> 0 | AL8: =ROUND(Y8-AK8,2) -> 0 | AM8: =ROUND(AG8-AK8,2) -> 225.31 | AN8: =ROUND(AM8*0.07,2) -> 15.77 | AO8: =ROUND(AM8*0.03,2) -> 6.76 | AP8: =ROUND(AH8+AI8+AJ8-AL8-AN8-AO8,2) -> 4.51 | AQ8: ="TJ"&A8 -> TJ202512011145000566762 | AR8: =IF(E8="无全额",0,MID(E8,4,2)*1) -> 0.06
A9: 202512011203000030494 | B9: 深圳中外运物流有限公司 | C9: 劳务承揽 | D9: 承揽业务 | E9: 电票（6%） | F9: =ROUND(SUMIF([1]开票!$A$2:$A$1750,[1]申请!AQ9,[1]开票!$C$2:$C$1750),2) -> #VALUE! | G9: =ROUND(SUMIF([1]开票!$A$2:$A$1750,[1]申请!AQ9,[1]开票!$D$2:$D$1750),2) -> 0 | H9: =ROUND(SUMIF([1]开票!$A$2:$A$1750,[1]申请!AQ9,[1]开票!$E$2:$E$1750),2) -> 4394.8 | I9: =SUM(F9:H9) -> #VALUE! | L9: 77641.54 | AD9: =SUM(J9:AC9) -> 77641.54 | AE9: =AD9-SUM(J9:AC9) -> 0 | AF9: =AD9-I9 -> #VALUE! | AG9: =ROUND(H9,2) -> 4394.8 | AH9: =ROUND(AG9*0.07,2) -> 307.64 | AI9: =ROUND(AG9*0.03,2) -> 131.84 | AJ9: =ROUND(AG9*0.02,2) -> 87.9 | AK9: =IF(AR9,Y9/(AR9*1.12)*AR9,0) -> 0 | AL9: =ROUND(Y9-AK9,2) -> 0 | AM9: =ROUND(AG9-AK9,2) -> 4394.8 | AN9: =ROUND(AM9*0.07,2) -> 307.64 | AO9: =ROUND(AM9*0.03,2) -> 131.84 | AP9: =ROUND(AH9+AI9+AJ9-AL9-AN9-AO9,2) -> 87.9 | AQ9: ="TJ"&A9 -> TJ202512011203000030494 | AR9: =IF(E9="无全额",0,MID(E9,4,2)*1) -> 0.06
A10: 202512011334000210352 | B10: 周老师(百果园) | C10: 劳务承揽 | D10: 承揽业务 | E10: 专票（6%） | F10: =ROUND(SUMIF([1]开票!$A$2:$A$1750,[1]申请!AQ10,[1]开票!$C$2:$C$1750),2) -> 25153.77 | G10: =ROUND(SUMIF([1]开票!$A$2:$A$1750,[1]申请!AQ10,[1]开票!$D$2:$D$1750),2) -> 0 | H10: =ROUND(SUMIF([1]开票!$A$2:$A$1750,[1]申请!AQ10,[1]开票!$E$2:$E$1750),2) -> 1509.23 | I10: =SUM(F10:H10) -> 26663 | L10: 26663 | AD10: =SUM(J10:AC10) -> 26663 | AE10: =AD10-SUM(J10:AC10) -> 0 | AF10: =AD10-I10 -> 0 | AG10: =ROUND(H10,2) -> 1509.23 | AH10: =ROUND(AG10*0.07,2) -> 105.65 | AI10: =ROUND(AG10*0.03,2) -> 45.28 | AJ10: =ROUND(AG10*0.02,2) -> 30.18 | AK10: =IF(AR10,Y10/(AR10*1.12)*AR10,0) -> 0 | AL10: =ROUND(Y10-AK10,2) -> 0 | AM10: =ROUND(AG10-AK10,2) -> 1509.23 | AN10: =ROUND(AM10*0.07,2) -> 105.65 | AO10: =ROUND(AM10*0.03,2) -> 45.28 | AP10: =ROUND(AH10+AI10+AJ10-AL10-AN10-AO10,2) -> 30.18 | AQ10: ="TJ"&A10 -> TJ202512011334000210352 | AR10: =IF(E10="无全额",0,MID(E10,4,2)*1) -> 0.06
A11: 202512011519000128722 | B11: 深圳市万科物业服务有限公司东莞茶山分公司 | C11: 劳务派遣 | D11: 派遣业务 | E11: 专票（5%） | F11: =ROUND(SUMIF([1]开票!$A$2:$A$1750,[1]申请!AQ11,[1]开票!$C$2:$C$1750),2) -> #VALUE! | G11: =ROUND(SUMIF([1]开票!$A$2:$A$1750,[1]申请!AQ11,[1]开票!$D$2:$D$1750),2) -> 103040.29 | H11: =ROUND(SUMIF([1]开票!$A$2:$A$1750,[1]申请!AQ11,[1]开票!$E$2:$E$1750),2) -> 39.1 | I11: =SUM(F11:H11) -> #VALUE! | J11: 782 | S11: 84594.74 | T11: 264.58 | U11: 17874.97 | W11: 306 | Y11: 39.1 | AD11: =SUM(J11:AC11) -> 103861.39 | AE11: =AD11-SUM(J11:AC11) -> 0 | AF11: =AD11-I11 -> #VALUE! | AG11: =ROUND(H11,2) -> 39.1 | AH11: =ROUND(AG11*0.07,2) -> 2.74 | AI11: =ROUND(AG11*0.03,2) -> 1.17 | AJ11: =ROUND(AG11*0.02,2) -> 0.78 | AK11: =IF(AR11,Y11/(AR11*1.12)*AR11,0) -> 34.910714 | AL11: =ROUND(Y11-AK11,2) -> 4.19 | AM11: =ROUND(AG11-AK11,2) -> 4.19 | AN11: =ROUND(AM11*0.07,2) -> 0.29 | AO11: =ROUND(AM11*0.03,2) -> 0.13 | AP11: =ROUND(AH11+AI11+AJ11-AL11-AN11-AO11,2) -> 0.08 | AQ11: ="TJ"&A11 -> TJ202512011519000128722 | AR11: =IF(E11="无全额",0,MID(E11,4,2)*1) -> 0.05
A12: 202512011524000290727 | B12: 东莞万江金鳌城市资源经营管理有限公司 | C12: 劳务派遣 | D12: 派遣业务 | E12: 专票（5%） | F12: =ROUND(SUMIF([1]开票!$A$2:$A$1750,[1]申请!AQ12,[1]开票!$C$2:$C$1750),2) -> 460 | G12: =ROUND(SUMIF([1]开票!$A$2:$A$1750,[1]申请!AQ12,[1]开票!$D$2:$D$1750),2) -> 62566.95 | H12: =ROUND(SUMIF([1]开票!$A$2:$A$1750,[1]申请!AQ12,[1]开票!$E$2:$E$1750),2) -> 23 | I12: =SUM(F12:H12) -> 63049.95 | J12: 460 | S12: 52661.58 | T12: 90.3 | U12: 9635.07 | W12: 180 | Y12: 23 | AD12: =SUM(J12:AC12) -> 63049.95 | AE12: =AD12-SUM(J12:AC12) -> 0 | AF12: =AD12-I12 -> 0 | AG12: =ROUND(H12,2) -> 23 | AH12: =ROUND(AG12*0.07,2) -> 1.61 | AI12: =ROUND(AG12*0.03,2) -> 0.69 | AJ12: =ROUND(AG12*0.02,2) -> 0.46 | AK12: =IF(AR12,Y12/(AR12*1.12)*AR12,0) -> 20.535714 | AL12: =ROUND(Y12-AK12,2) -> 2.46 | AM12: =ROUND(AG12-AK12,2) -> 2.46 | AN12: =ROUND(AM12*0.07,2) -> 0.17 | AO12: =ROUND(AM12*0.03,2) -> 0.07 | AP12: =ROUND(AH12+AI12+AJ12-AL12-AN12-AO12,2) -> 0.06 | AQ12: ="TJ"&A12 -> TJ202512011524000290727 | AR12: =IF(E12="无全额",0,MID(E12,4,2)*1) -> 0.05
A13: 202512011528000448156 | B13: 东莞万江金鳌城市资源经营管理有限公司 | C13: 劳务派遣 | D13: 派遣业务 | E13: 专票（5%） | F13: =ROUND(SUMIF([1]开票!$A$2:$A$1750,[1]申请!AQ13,[1]开票!$C$2:$C$1750),2) -> 92 | G13: =ROUND(SUMIF([1]开票!$A$2:$A$1750,[1]申请!AQ13,[1]开票!$D$2:$D$1750),2) -> 6459.84 | H13: =ROUND(SUMIF([1]开票!$A$2:$A$1750,[1]申请!AQ13,[1]开票!$E$2:$E$1750),2) -> 4.6 | I13: =SUM(F13:H13) -> 6556.44 | J13: 92 | S13: 6400 | T13: 0 | U13: 23.84 | W13: 36 | Y13: 4.6 | AD13: =SUM(J13:AC13) -> 6556.44 | AE13: =AD13-SUM(J13:AC13) -> 0 | AF13: =AD13-I13 -> 0 | AG13: =ROUND(H13,2) -> 4.6 | AH13: =ROUND(AG13*0.07,2) -> 0.32 | AI13: =ROUND(AG13*0.03,2) -> 0.14 | AJ13: =ROUND(AG13*0.02,2) -> 0.09 | AK13: =IF(AR13,Y13/(AR13*1.12)*AR13,0) -> 4.1071429 | AL13: =ROUND(Y13-AK13,2) -> 0.49 | AM13: =ROUND(AG13-AK13,2) -> 0.49 | AN13: =ROUND(AM13*0.07,2) -> 0.03 | AO13: =ROUND(AM13*0.03,2) -> 0.01 | AP13: =ROUND(AH13+AI13+AJ13-AL13-AN13-AO13,2) -> 0.02 | AQ13: ="TJ"&A13 -> TJ202512011528000448156 | AR13: =IF(E13="无全额",0,MID(E13,4,2)*1) -> 0.05
A14: 202512011754000073051 | B14: 广州市南海中学 | C14: 劳务派遣 | D14: 派遣业务 | E14: 专票（5%） | F14: =ROUND(SUMIF([1]开票!$A$2:$A$1750,[1]申请!AQ14,[1]开票!$C$2:$C$1750),2) -> 2042.85 | G14: =ROUND(SUMIF([1]开票!$A$2:$A$1750,[1]申请!AQ14,[1]开票!$D$2:$D$1750),2) -> 270816.8 | H14: =ROUND(SUMIF([1]开票!$A$2:$A$1750,[1]申请!AQ14,[1]开票!$E$2:$E$1750),2) -> 102.15 | I14: =SUM(F14:H14) -> 272961.8 | J14: 2145 | S14: 183162.12 | T14: 986.61 | U14: 65701.19 | V14: 19470 | W14: 0 | X14: 1496.88 | AD14: =SUM(J14:AC14) -> 272961.8 | AE14: =AD14-SUM(J14:AC14) -> 0 | AF14: =AD14-I14 -> 0 | AG14: =ROUND(H14,2) -> 102.15 | AH14: =ROUND(AG14*0.07,2) -> 7.15 | AI14: =ROUND(AG14*0.03,2) -> 3.06 | AJ14: =ROUND(AG14*0.02,2) -> 2.04 | AK14: =IF(AR14,Y14/(AR14*1.12)*AR14,0) -> 0 | AL14: =ROUND(Y14-AK14,2) -> 0 | AM14: =ROUND(AG14-AK14,2) -> 102.15 | AN14: =ROUND(AM14*0.07,2) -> 7.15 | AO14: =ROUND(AM14*0.03,2) -> 3.06 | AP14: =ROUND(AH14+AI14+AJ14-AL14-AN14-AO14,2) -> 2.04 | AQ14: ="TJ"&A14 -> TJ202512011754000073051 | AR14: =IF(E14="无全额",0,MID(E14,4,2)*1) -> 0.05
A15: 202512020912000234377 | B15: 广州市第一中学 | C15: 劳务派遣 | D15: 派遣业务 | E15: 普票（5%） | F15: =ROUND(SUMIF([1]开票!$A$2:$A$1750,[1]申请!AQ15,[1]开票!$C$2:$C$1750),2) -> 0 | G15: =ROUND(SUMIF([1]开票!$A$2:$A$1750,[1]申请!AQ15,[1]开票!$D$2:$D$1750),2) -> 239913.88 | H15: =ROUND(SUMIF([1]开票!$A$2:$A$1750,[1]申请!AQ15,[1]开票!$E$2:$E$1750),2) -> 0 | I15: =SUM(F15:H15) -> 239913.88 | S15: 239913.88 | AD15: =SUM(J15:AC15) -> 239913.88 | AE15: =AD15-SUM(J15:AC15) -> 0 | AF15: =AD15-I15 -> 0 | AG15: =ROUND(H15,2) -> 0 | AH15: =ROUND(AG15*0.07,2) -> 0 | AI15: =ROUND(AG15*0.03,2) -> 0 | AJ15: =ROUND(AG15*0.02,2) -> 0 | AK15: =IF(AR15,Y15/(AR15*1.12)*AR15,0) -> 0 | AL15: =ROUND(Y15-AK15,2) -> 0 | AM15: =ROUND(AG15-AK15,2) -> 0 | AN15: =ROUND(AM15*0.07,2) -> 0 | AO15: =ROUND(AM15*0.03,2) -> 0 | AP15: =ROUND(AH15+AI15+AJ15-AL15-AN15-AO15,2) -> 0 | AQ15: ="TJ"&A15 -> TJ202512020912000234377 | AR15: =IF(E15="无全额",0,MID(E15,4,2)*1) -> 0.05
A16: 202512020914000230838 | B16: 广州市第一中学 | C16: 劳务派遣 | D16: 派遣业务 | E16: 专票（6%） | F16: =ROUND(SUMIF([1]开票!$A$2:$A$1750,[1]申请!AQ16,[1]开票!$C$2:$C$1750),2) -> 35.85 | G16: =ROUND(SUMIF([1]开票!$A$2:$A$1750,[1]申请!AQ16,[1]开票!$D$2:$D$1750),2) -> 0 | H16: =ROUND(SUMIF([1]开票!$A$2:$A$1750,[1]申请!AQ16,[1]开票!$E$2:$E$1750),2) -> 2.15 | I16: =SUM(F16:H16) -> 38 | P16: 11 | W16: 27 | AD16: =SUM(J16:AC16) -> 38 | AE16: =AD16-SUM(J16:AC16) -> 0 | AF16: =AD16-I16 -> 0 | AG16: =ROUND(H16,2) -> 2.15 | AH16: =ROUND(AG16*0.07,2) -> 0.15 | AI16: =ROUND(AG16*0.03,2) -> 0.06 | AJ16: =ROUND(AG16*0.02,2) -> 0.04 | AK16: =IF(AR16,Y16/(AR16*1.12)*AR16,0) -> 0 | AL16: =ROUND(Y16-AK16,2) -> 0 | AM16: =ROUND(AG16-AK16,2) -> 2.15 | AN16: =ROUND(AM16*0.07,2) -> 0.15 | AO16: =ROUND(AM16*0.03,2) -> 0.06 | AP16: =ROUND(AH16+AI16+AJ16-AL16-AN16-AO16,2) -> 0.04 | AQ16: ="TJ"&A16 -> TJ202512020914000230838 | AR16: =IF(E16="无全额",0,MID(E16,4,2)*1) -> 0.06
A17: 202512020916000393523 | B17: 广州市第一中学 | C17: 劳务派遣 | D17: 派遣业务 | E17: 普票（5%） | F17: =ROUND(SUMIF([1]开票!$A$2:$A$1750,[1]申请!AQ17,[1]开票!$C$2:$C$1750),2) -> 557.14 | G17: =ROUND(SUMIF([1]开票!$A$2:$A$1750,[1]申请!AQ17,[1]开票!$D$2:$D$1750),2) -> 73517.47 | H17: =ROUND(SUMIF([1]开票!$A$2:$A$1750,[1]申请!AQ17,[1]开票!$E$2:$E$1750),2) -> 27.86 | I17: =SUM(F17:H17) -> 74102.47 | K17: 585 | S17: 53655.63 | T17: 741.33 | U17: 14741.63 | V17: 4016 | X17: 362.88 | AD17: =SUM(J17:AC17) -> 74102.47 | AE17: =AD17-SUM(J17:AC17) -> 0 | AF17: =AD17-I17 -> 0 | AG17: =ROUND(H17,2) -> 27.86 | AH17: =ROUND(AG17*0.07,2) -> 1.95 | AI17: =ROUND(AG17*0.03,2) -> 0.84 | AJ17: =ROUND(AG17*0.02,2) -> 0.56 | AK17: =IF(AR17,Y17/(AR17*1.12)*AR17,0) -> 0 | AL17: =ROUND(Y17-AK17,2) -> 0 | AM17: =ROUND(AG17-AK17,2) -> 27.86 | AN17: =ROUND(AM17*0.07,2) -> 1.95 | AO17: =ROUND(AM17*0.03,2) -> 0.84 | AP17: =ROUND(AH17+AI17+AJ17-AL17-AN17-AO17,2) -> 0.56 | AQ17: ="TJ"&A17 -> TJ202512020916000393523 | AR17: =IF(E17="无全额",0,MID(E17,4,2)*1) -> 0.05
A18: 202512020921000119648 | B18: 广州市第一中学 | C18: 劳务派遣 | D18: 派遣业务 | E18: 普票（5%） | F18: =ROUND(SUMIF([1]开票!$A$2:$A$1750,[1]申请!AQ18,[1]开票!$C$2:$C$1750),2) -> 1238.1 | G18: =ROUND(SUMIF([1]开票!$A$2:$A$1750,[1]申请!AQ18,[1]开票!$D$2:$D$1750),2) -> 182425.8 | H18: =ROUND(SUMIF([1]开票!$A$2:$A$1750,[1]申请!AQ18,[1]开票!$E$2:$E$1750),2) -> 61.9 | I18: =SUM(F18:H18) -> 183725.8 | K18: 1300 | S18: 136343.93 | T18: 1558.87 | U18: 36447.8 | V18: 7168 | X18: 907.2 | AD18: =SUM(J18:AC18) -> 183725.8 | AE18: =AD18-SUM(J18:AC18) -> 0 | AF18: =AD18-I18 -> 0 | AG18: =ROUND(H18,2) -> 61.9 | AH18: =ROUND(AG18*0.07,2) -> 4.33 | AI18: =ROUND(AG18*0.03,2) -> 1.86 | AJ18: =ROUND(AG18*0.02,2) -> 1.24 | AK18: =IF(AR18,Y18/(AR18*1.12)*AR18,0) -> 0 | AL18: =ROUND(Y18-AK18,2) -> 0 | AM18: =ROUND(AG18-AK18,2) -> 61.9 | AN18: =ROUND(AM18*0.07,2) -> 4.33 | AO18: =ROUND(AM18*0.03,2) -> 1.86 | AP18: =ROUND(AH18+AI18+AJ18-AL18-AN18-AO18,2) -> 1.24 | AQ18: ="TJ"&A18 -> TJ202512020921000119648 | AR18: =IF(E18="无全额",0,MID(E18,4,2)*1) -> 0.05
A19: 202512020927000032377 | B19: 广州市南海中学 | C19: 劳务派遣 | D19: 派遣业务 | E19: 专票（5%） | F19: =ROUND(SUMIF([1]开票!$A$2:$A$1750,[1]申请!AQ19,[1]开票!$C$2:$C$1750),2) -> 0 | G19: =ROUND(SUMIF([1]开票!$A$2:$A$1750,[1]申请!AQ19,[1]开票!$D$2:$D$1750),2) -> 12772.5 | H19: =ROUND(SUMIF([1]开票!$A$2:$A$1750,[1]申请!AQ19,[1]开票!$E$2:$E$1750),2) -> 0 | I19: =SUM(F19:H19) -> 12772.5 | J19: 0 | S19: 12772.5 | T19: 0 | U19: 0 | V19: 0 | W19: 0 | X19: 0 | AD19: =SUM(J19:AC19) -> 12772.5 | AE19: =AD19-SUM(J19:AC19) -> 0 | AF19: =AD19-I19 -> 0 | AG19: =ROUND(H19,2) -> 0 | AH19: =ROUND(AG19*0.07,2) -> 0 | AI19: =ROUND(AG19*0.03,2) -> 0 | AJ19: =ROUND(AG19*0.02,2) -> 0 | AK19: =IF(AR19,Y19/(AR19*1.12)*AR19,0) -> 0 | AL19: =ROUND(Y19-AK19,2) -> 0 | AM19: =ROUND(AG19-AK19,2) -> 0 | AN19: =ROUND(AM19*0.07,2) -> 0 | AO19: =ROUND(AM19*0.03,2) -> 0 | AP19: =ROUND(AH19+AI19+AJ19-AL19-AN19-AO19,2) -> 0 | AQ19: ="TJ"&A19 -> TJ202512020927000032377 | AR19: =IF(E19="无全额",0,MID(E19,4,2)*1) -> 0.05
A20: 202512021410000083517 | B20: 软通动力信息技术（集团）股份有限公司 | C20: 劳务承揽 | D20: 小时间承揽 | E20: 专票（6%） | F20: =ROUND(SUMIF([1]开票!$A$2:$A$1750,[1]申请!AQ20,[1]开票!$C$2:$C$1750),2) -> 111307.88 | G20: =ROUND(SUMIF([1]开票!$A$2:$A$1750,[1]申请!AQ20,[1]开票!$D$2:$D$1750),2) -> 0 | H20: =ROUND(SUMIF([1]开票!$A$2:$A$1750,[1]申请!AQ20,[1]开票!$E$2:$E$1750),2) -> 6678.47 | I20: =SUM(F20:H20) -> 117986.35 | Q20: 7684.25 | W20: 527.1 | Z20: 109775 | AD20: =SUM(J20:AC20) -> 117986.35 | AE20: =AD20-SUM(J20:AC20) -> 0 | AF20: =AD20-I20 -> 0 | AG20: =ROUND(H20,2) -> 6678.47 | AH20: =ROUND(AG20*0.07,2) -> 467.49 | AI20: =ROUND(AG20*0.03,2) -> 200.35 | AJ20: =ROUND(AG20*0.02,2) -> 133.57 | AK20: =IF(AR20,Y20/(AR20*1.12)*AR20,0) -> 0 | AL20: =ROUND(Y20-AK20,2) -> 0 | AM20: =ROUND(AG20-AK20,2) -> 6678.47 | AN20: =ROUND(AM20*0.07,2) -> 467.49 | AO20: =ROUND(AM20*0.03,2) -> 200.35 | AP20: =ROUND(AH20+AI20+AJ20-AL20-AN20-AO20,2) -> 133.57 | AQ20: ="TJ"&A20 -> TJ202512021410000083517 | AR20: =IF(E20="无全额",0,MID(E20,4,2)*1) -> 0.06
A21: 202512021519000271014 | B21: 广州市南海中学 | C21: 劳务派遣 | D21: 派遣业务 | E21: 专票（5%） | F21: =ROUND(SUMIF([1]开票!$A$2:$A$1750,[1]申请!AQ21,[1]开票!$C$2:$C$1750),2) -> 309.52 | G21: =ROUND(SUMIF([1]开票!$A$2:$A$1750,[1]申请!AQ21,[1]开票!$D$2:$D$1750),2) -> 28528.58 | H21: =ROUND(SUMIF([1]开票!$A$2:$A$1750,[1]申请!AQ21,[1]开票!$E$2:$E$1750),2) -> 15.48 | I21: =SUM(F21:H21) -> 28853.58 | J21: 325 | S21: 24000 | T21: 4528.58 | U21: 0 | V21: 0 | W21: 0 | X21: 0 | AD21: =SUM(J21:AC21) -> 28853.58 | AE21: =AD21-SUM(J21:AC21) -> 0 | AF21: =AD21-I21 -> 0 | AG21: =ROUND(H21,2) -> 15.48 | AH21: =ROUND(AG21*0.07,2) -> 1.08 | AI21: =ROUND(AG21*0.03,2) -> 0.46 | AJ21: =ROUND(AG21*0.02,2) -> 0.31 | AK21: =IF(AR21,Y21/(AR21*1.12)*AR21,0) -> 0 | AL21: =ROUND(Y21-AK21,2) -> 0 | AM21: =ROUND(AG21-AK21,2) -> 15.48 | AN21: =ROUND(AM21*0.07,2) -> 1.08 | AO21: =ROUND(AM21*0.03,2) -> 0.46 | AP21: =ROUND(AH21+AI21+AJ21-AL21-AN21-AO21,2) -> 0.31 | AQ21: ="TJ"&A21 -> TJ202512021519000271014 | AR21: =IF(E21="无全额",0,MID(E21,4,2)*1) -> 0.05
A22: 202512021609000063803 | B22: 软通动力信息技术（集团）股份有限公司 | C22: 劳务承揽 | D22: 小时间承揽 | E22: 专票（6%） | F22: =ROUND(SUMIF([1]开票!$A$2:$A$1750,[1]申请!AQ22,[1]开票!$C$2:$C$1750),2) -> 1312.26 | G22: =ROUND(SUMIF([1]开票!$A$2:$A$1750,[1]申请!AQ22,[1]开票!$D$2:$D$1750),2) -> 0 | H22: =ROUND(SUMIF([1]开票!$A$2:$A$1750,[1]申请!AQ22,[1]开票!$E$2:$E$1750),2) -> 78.74 | I22: =SUM(F22:H22) -> 1391 | Q22: 91 | Z22: 1300 | AD22: =SUM(J22:AC22) -> 1391 | AE22: =AD22-SUM(J22:AC22) -> 0 | AF22: =AD22-I22 -> 0 | AG22: =ROUND(H22,2) -> 78.74 | AH22: =ROUND(AG22*0.07,2) -> 5.51 | AI22: =ROUND(AG22*0.03,2) -> 2.36 | AJ22: =ROUND(AG22*0.02,2) -> 1.57 | AK22: =IF(AR22,Y22/(AR22*1.12)*AR22,0) -> 0 | AL22: =ROUND(Y22-AK22,2) -> 0 | AM22: =ROUND(AG22-AK22,2) -> 78.74 | AN22: =ROUND(AM22*0.07,2) -> 5.51 | AO22: =ROUND(AM22*0.03,2) -> 2.36 | AP22: =ROUND(AH22+AI22+AJ22-AL22-AN22-AO22,2) -> 1.57 | AQ22: ="TJ"&A22 -> TJ202512021609000063803 | AR22: =IF(E22="无全额",0,MID(E22,4,2)*1) -> 0.06
A23: 202512021611000107980 | B23: 软通动力信息技术（集团）股份有限公司 | C23: 劳务承揽 | D23: 小时间承揽 | E23: 专票（6%） | F23: =ROUND(SUMIF([1]开票!$A$2:$A$1750,[1]申请!AQ23,[1]开票!$C$2:$C$1750),2) -> 39632.98 | G23: =ROUND(SUMIF([1]开票!$A$2:$A$1750,[1]申请!AQ23,[1]开票!$D$2:$D$1750),2) -> 0 | H23: =ROUND(SUMIF([1]开票!$A$2:$A$1750,[1]申请!AQ23,[1]开票!$E$2:$E$1750),2) -> 2377.98 | I23: =SUM(F23:H23) -> 42010.96 | Q23: 2748.38 | Z23: 39262.58 | AD23: =SUM(J23:AC23) -> 42010.96 | AE23: =AD23-SUM(J23:AC23) -> 0 | AF23: =AD23-I23 -> 0 | AG23: =ROUND(H23,2) -> 2377.98 | AH23: =ROUND(AG23*0.07,2) -> 166.46 | AI23: =ROUND(AG23*0.03,2) -> 71.34 | AJ23: =ROUND(AG23*0.02,2) -> 47.56 | AK23: =IF(AR23,Y23/(AR23*1.12)*AR23,0) -> 0 | AL23: =ROUND(Y23-AK23,2) -> 0 | AM23: =ROUND(AG23-AK23,2) -> 2377.98 | AN23: =ROUND(AM23*0.07,2) -> 166.46 | AO23: =ROUND(AM23*0.03,2) -> 71.34 | AP23: =ROUND(AH23+AI23+AJ23-AL23-AN23-AO23,2) -> 47.56 | AQ23: ="TJ"&A23 -> TJ202512021611000107980 | AR23: =IF(E23="无全额",0,MID(E23,4,2)*1) -> 0.06
A24: 202512021613000555164 | B24: 软通动力信息技术（集团）股份有限公司 | C24: 劳务承揽 | D24: 小时间承揽 | E24: 专票（6%） | F24: =ROUND(SUMIF([1]开票!$A$2:$A$1750,[1]申请!AQ24,[1]开票!$C$2:$C$1750),2) -> 90166.55 | G24: =ROUND(SUMIF([1]开票!$A$2:$A$1750,[1]申请!AQ24,[1]开票!$D$2:$D$1750),2) -> 0 | H24: =ROUND(SUMIF([1]开票!$A$2:$A$1750,[1]申请!AQ24,[1]开票!$E$2:$E$1750),2) -> 5409.99 | I24: =SUM(F24:H24) -> 95576.54 | Q24: 6192.9 | W24: 913.64 | Z24: 88470 | AD24: =SUM(J24:AC24) -> 95576.54 | AE24: =AD24-SUM(J24:AC24) -> 0 | AF24: =AD24-I24 -> 0 | AG24: =ROUND(H24,2) -> 5409.99 | AH24: =ROUND(AG24*0.07,2) -> 378.7 | AI24: =ROUND(AG24*0.03,2) -> 162.3 | AJ24: =ROUND(AG24*0.02,2) -> 108.2 | AK24: =IF(AR24,Y24/(AR24*1.12)*AR24,0) -> 0 | AL24: =ROUND(Y24-AK24,2) -> 0 | AM24: =ROUND(AG24-AK24,2) -> 5409.99 | AN24: =ROUND(AM24*0.07,2) -> 378.7 | AO24: =ROUND(AM24*0.03,2) -> 162.3 | AP24: =ROUND(AH24+AI24+AJ24-AL24-AN24-AO24,2) -> 108.2 | AQ24: ="TJ"&A24 -> TJ202512021613000555164 | AR24: =IF(E24="无全额",0,MID(E24,4,2)*1) -> 0.06
A25: 202512021636000598013 | B25: 蚂蚁HRO | C25: 劳务承揽 | D25: 承揽业务 | E25: 专票（6%） | F25: =ROUND(SUMIF([1]开票!$A$2:$A$1750,[1]申请!AQ25,[1]开票!$C$2:$C$1750),2) -> 13469.15 | G25: =ROUND(SUMIF([1]开票!$A$2:$A$1750,[1]申请!AQ25,[1]开票!$D$2:$D$1750),2) -> 0 | H25: =ROUND(SUMIF([1]开票!$A$2:$A$1750,[1]申请!AQ25,[1]开票!$E$2:$E$1750),2) -> 808.15 | I25: =SUM(F25:H25) -> 14277.3 | J25: 14277.3 | AD25: =SUM(J25:AC25) -> 14277.3 | AE25: =AD25-SUM(J25:AC25) -> 0 | AF25: =AD25-I25 -> 0 | AG25: =ROUND(H25,2) -> 808.15 | AH25: =ROUND(AG25*0.07,2) -> 56.57 | AI25: =ROUND(AG25*0.03,2) -> 24.24 | AJ25: =ROUND(AG25*0.02,2) -> 16.16 | AK25: =IF(AR25,Y25/(AR25*1.12)*AR25,0) -> 0 | AL25: =ROUND(Y25-AK25,2) -> 0 | AM25: =ROUND(AG25-AK25,2) -> 808.15 | AN25: =ROUND(AM25*0.07,2) -> 56.57 | AO25: =ROUND(AM25*0.03,2) -> 24.24 | AP25: =ROUND(AH25+AI25+AJ25-AL25-AN25-AO25,2) -> 16.16 | AQ25: ="TJ"&A25 -> TJ202512021636000598013 | AR25: =IF(E25="无全额",0,MID(E25,4,2)*1) -> 0.06
A26: 202512021639000011329 | B26: 蚂蚁HRO | C26: 劳务承揽 | D26: 承揽业务 | E26: 专票（6%） | F26: =ROUND(SUMIF([1]开票!$A$2:$A$1750,[1]申请!AQ26,[1]开票!$C$2:$C$1750),2) -> 118324.94 | G26: =ROUND(SUMIF([1]开票!$A$2:$A$1750,[1]申请!AQ26,[1]开票!$D$2:$D$1750),2) -> 0 | H26: =ROUND(SUMIF([1]开票!$A$2:$A$1750,[1]申请!AQ26,[1]开票!$E$2:$E$1750),2) -> 7099.5 | I26: =SUM(F26:H26) -> 125424.44 | J26: 125424.44 | AD26: =SUM(J26:AC26) -> 125424.44 | AE26: =AD26-SUM(J26:AC26) -> 0 | AF26: =AD26-I26 -> 0 | AG26: =ROUND(H26,2) -> 7099.5 | AH26: =ROUND(AG26*0.07,2) -> 496.97 | AI26: =ROUND(AG26*0.03,2) -> 212.99 | AJ26: =ROUND(AG26*0.02,2) -> 141.99 | AK26: =IF(AR26,Y26/(AR26*1.12)*AR26,0) -> 0 | AL26: =ROUND(Y26-AK26,2) -> 0 | AM26: =ROUND(AG26-AK26,2) -> 7099.5 | AN26: =ROUND(AM26*0.07,2) -> 496.97 | AO26: =ROUND(AM26*0.03,2) -> 212.99 | AP26: =ROUND(AH26+AI26+AJ26-AL26-AN26-AO26,2) -> 141.99 | AQ26: ="TJ"&A26 -> TJ202512021639000011329 | AR26: =IF(E26="无全额",0,MID(E26,4,2)*1) -> 0.06
A27: 202512021650000521680 | B27: 蚂蚁HRO | C27: 劳务承揽 | D27: 承揽业务 | E27: 专票（6%） | F27: =ROUND(SUMIF([1]开票!$A$2:$A$1750,[1]申请!AQ27,[1]开票!$C$2:$C$1750),2) -> 12666.22 | G27: =ROUND(SUMIF([1]开票!$A$2:$A$1750,[1]申请!AQ27,[1]开票!$D$2:$D$1750),2) -> 0 | H27: =ROUND(SUMIF([1]开票!$A$2:$A$1750,[1]申请!AQ27,[1]开票!$E$2:$E$1750),2) -> 759.97 | I27: =SUM(F27:H27) -> 13426.19 | J27: 13426.19 | AD27: =SUM(J27:AC27) -> 13426.19 | AE27: =AD27-SUM(J27:AC27) -> 0 | AF27: =AD27-I27 -> 0 | AG27: =ROUND(H27,2) -> 759.97 | AH27: =ROUND(AG27*0.07,2) -> 53.2 | AI27: =ROUND(AG27*0.03,2) -> 22.8 | AJ27: =ROUND(AG27*0.02,2) -> 15.2 | AK27: =IF(AR27,Y27/(AR27*1.12)*AR27,0) -> 0 | AL27: =ROUND(Y27-AK27,2) -> 0 | AM27: =ROUND(AG27-AK27,2) -> 759.97 | AN27: =ROUND(AM27*0.07,2) -> 53.2 | AO27: =ROUND(AM27*0.03,2) -> 22.8 | AP27: =ROUND(AH27+AI27+AJ27-AL27-AN27-AO27,2) -> 15.2 | AQ27: ="TJ"&A27 -> TJ202512021650000521680 | AR27: =IF(E27="无全额",0,MID(E27,4,2)*1) -> 0.06
A28: 202512021653000468302 | B28: 蚂蚁HRO | C28: 劳务承揽 | D28: 承揽业务 | E28: 专票（6%） | F28: =ROUND(SUMIF([1]开票!$A$2:$A$1750,[1]申请!AQ28,[1]开票!$C$2:$C$1750),2) -> 19424.18 | G28: =ROUND(SUMIF([1]开票!$A$2:$A$1750,[1]申请!AQ28,[1]开票!$D$2:$D$1750),2) -> 0 | H28: =ROUND(SUMIF([1]开票!$A$2:$A$1750,[1]申请!AQ28,[1]开票!$E$2:$E$1750),2) -> 1165.45 | I28: =SUM(F28:H28) -> 20589.63 | J28: 20589.63 | AD28: =SUM(J28:AC28) -> 20589.63 | AE28: =AD28-SUM(J28:AC28) -> 0 | AF28: =AD28-I28 -> 0 | AG28: =ROUND(H28,2) -> 1165.45 | AH28: =ROUND(AG28*0.07,2) -> 81.58 | AI28: =ROUND(AG28*0.03,2) -> 34.96 | AJ28: =ROUND(AG28*0.02,2) -> 23.31 | AK28: =IF(AR28,Y28/(AR28*1.12)*AR28,0) -> 0 | AL28: =ROUND(Y28-AK28,2) -> 0 | AM28: =ROUND(AG28-AK28,2) -> 1165.45 | AN28: =ROUND(AM28*0.07,2) -> 81.58 | AO28: =ROUND(AM28*0.03,2) -> 34.96 | AP28: =ROUND(AH28+AI28+AJ28-AL28-AN28-AO28,2) -> 23.31 | AQ28: ="TJ"&A28 -> TJ202512021653000468302 | AR28: =IF(E28="无全额",0,MID(E28,4,2)*1) -> 0.06
A29: 202512021654000236881 | B29: 蚂蚁HRO | C29: 劳务承揽 | D29: 承揽业务 | E29: 专票（6%） | F29: =ROUND(SUMIF([1]开票!$A$2:$A$1750,[1]申请!AQ29,[1]开票!$C$2:$C$1750),2) -> 13932.08 | G29: =ROUND(SUMIF([1]开票!$A$2:$A$1750,[1]申请!AQ29,[1]开票!$D$2:$D$1750),2) -> 0 | H29: =ROUND(SUMIF([1]开票!$A$2:$A$1750,[1]申请!AQ29,[1]开票!$E$2:$E$1750),2) -> 835.92 | I29: =SUM(F29:H29) -> 14768 | J29: 14768 | AD29: =SUM(J29:AC29) -> 14768 | AE29: =AD29-SUM(J29:AC29) -> 0 | AF29: =AD29-I29 -> 0 | AG29: =ROUND(H29,2) -> 835.92 | AH29: =ROUND(AG29*0.07,2) -> 58.51 | AI29: =ROUND(AG29*0.03,2) -> 25.08 | AJ29: =ROUND(AG29*0.02,2) -> 16.72 | AK29: =IF(AR29,Y29/(AR29*1.12)*AR29,0) -> 0 | AL29: =ROUND(Y29-AK29,2) -> 0 | AM29: =ROUND(AG29-AK29,2) -> 835.92 | AN29: =ROUND(AM29*0.07,2) -> 58.51 | AO29: =ROUND(AM29*0.03,2) -> 25.08 | AP29: =ROUND(AH29+AI29+AJ29-AL29-AN29-AO29,2) -> 16.72 | AQ29: ="TJ"&A29 -> TJ202512021654000236881 | AR29: =IF(E29="无全额",0,MID(E29,4,2)*1) -> 0.06
A30: 202512021655000124061 | B30: 北京京东世纪贸易有限公司 | C30: 猎头服务 | D30: 猎头业务 | E30: 专票（6%） | F30: =ROUND(SUMIF([1]开票!$A$2:$A$1750,[1]申请!AQ30,[1]开票!$C$2:$C$1750),2) -> 6132.08 | G30: =ROUND(SUMIF([1]开票!$A$2:$A$1750,[1]申请!AQ30,[1]开票!$D$2:$D$1750),2) -> 0 | H30: =ROUND(SUMIF([1]开票!$A$2:$A$1750,[1]申请!AQ30,[1]开票!$E$2:$E$1750),2) -> 367.92 | I30: =SUM(F30:H30) -> 6500 | N30: 6500 | AD30: =SUM(J30:AC30) -> 6500 | AE30: =AD30-SUM(J30:AC30) -> 0 | AF30: =AD30-I30 -> 0 | AG30: =ROUND(H30,2) -> 367.92 | AH30: =ROUND(AG30*0.07,2) -> 25.75 | AI30: =ROUND(AG30*0.03,2) -> 11.04 | AJ30: =ROUND(AG30*0.02,2) -> 7.36 | AK30: =IF(AR30,Y30/(AR30*1.12)*AR30,0) -> 0 | AL30: =ROUND(Y30-AK30,2) -> 0 | AM30: =ROUND(AG30-AK30,2) -> 367.92 | AN30: =ROUND(AM30*0.07,2) -> 25.75 | AO30: =ROUND(AM30*0.03,2) -> 11.04 | AP30: =ROUND(AH30+AI30+AJ30-AL30-AN30-AO30,2) -> 7.36 | AQ30: ="TJ"&A30 -> TJ202512021655000124061 | AR30: =IF(E30="无全额",0,MID(E30,4,2)*1) -> 0.06
A31: 202512021655000562923 | B31: 蚂蚁HRO | C31: 劳务承揽 | D31: 承揽业务 | E31: 专票（6%） | F31: =ROUND(SUMIF([1]开票!$A$2:$A$1750,[1]申请!AQ31,[1]开票!$C$2:$C$1750),2) -> 2497.15 | G31: =ROUND(SUMIF([1]开票!$A$2:$A$1750,[1]申请!AQ31,[1]开票!$D$2:$D$1750),2) -> 0 | H31: =ROUND(SUMIF([1]开票!$A$2:$A$1750,[1]申请!AQ31,[1]开票!$E$2:$E$1750),2) -> 149.83 | I31: =SUM(F31:H31) -> 2646.98 | J31: 2646.98 | AD31: =SUM(J31:AC31) -> 2646.98 | AE31: =AD31-SUM(J31:AC31) -> 0 | AF31: =AD31-I31 -> 0 | AG31: =ROUND(H31,2) -> 149.83 | AH31: =ROUND(AG31*0.07,2) -> 10.49 | AI31: =ROUND(AG31*0.03,2) -> 4.49 | AJ31: =ROUND(AG31*0.02,2) -> 3 | AK31: =IF(AR31,Y31/(AR31*1.12)*AR31,0) -> 0 | AL31: =ROUND(Y31-AK31,2) -> 0 | AM31: =ROUND(AG31-AK31,2) -> 149.83 | AN31: =ROUND(AM31*0.07,2) -> 10.49 | AO31: =ROUND(AM31*0.03,2) -> 4.49 | AP31: =ROUND(AH31+AI31+AJ31-AL31-AN31-AO31,2) -> 3 | AQ31: ="TJ"&A31 -> TJ202512021655000562923 | AR31: =IF(E31="无全额",0,MID(E31,4,2)*1) -> 0.06
A32: 202512021749000195269 | B32: 广州白云山敬修堂药业股份有限公司 | C32: 劳务承揽 | D32: 承揽业务 | E32: 专票（6%） | F32: =ROUND(SUMIF([1]开票!$A$2:$A$1750,[1]申请!AQ32,[1]开票!$C$2:$C$1750),2) -> 20572.64 | G32: =ROUND(SUMIF([1]开票!$A$2:$A$1750,[1]申请!AQ32,[1]开票!$D$2:$D$1750),2) -> 0 | H32: =ROUND(SUMIF([1]开票!$A$2:$A$1750,[1]申请!AQ32,[1]开票!$E$2:$E$1750),2) -> 1234.36 | I32: =SUM(F32:H32) -> 21807 | L32: 21807 | AD32: =SUM(J32:AC32) -> 21807 | AE32: =AD32-SUM(J32:AC32) -> 0 | AF32: =AD32-I32 -> 0 | AG32: =ROUND(H32,2) -> 1234.36 | AH32: =ROUND(AG32*0.07,2) -> 86.41 | AI32: =ROUND(AG32*0.03,2) -> 37.03 | AJ32: =ROUND(AG32*0.02,2) -> 24.69 | AK32: =IF(AR32,Y32/(AR32*1.12)*AR32,0) -> 0 | AL32: =ROUND(Y32-AK32,2) -> 0 | AM32: =ROUND(AG32-AK32,2) -> 1234.36 | AN32: =ROUND(AM32*0.07,2) -> 86.41 | AO32: =ROUND(AM32*0.03,2) -> 37.03 | AP32: =ROUND(AH32+AI32+AJ32-AL32-AN32-AO32,2) -> 24.69 | AQ32: ="TJ"&A32 -> TJ202512021749000195269 | AR32: =IF(E32="无全额",0,MID(E32,4,2)*1) -> 0.06
A33: 202512031007000000620 | B33: 畅捷通信息技术股份有限公司 | C33: 劳务派遣 | D33: 派遣业务 | E33: 专票（6%） | F33: =ROUND(SUMIF([1]开票!$A$2:$A$1750,[1]申请!AQ33,[1]开票!$C$2:$C$1750),2) -> 227601.17 | G33: =ROUND(SUMIF([1]开票!$A$2:$A$1750,[1]申请!AQ33,[1]开票!$D$2:$D$1750),2) -> 0 | H33: =ROUND(SUMIF([1]开票!$A$2:$A$1750,[1]申请!AQ33,[1]开票!$E$2:$E$1750),2) -> 13656.07 | I33: =SUM(F33:H33) -> 241257.24 | S33: 151930.3 | T33: 50.15 | U33: 44906.29 | V33: 1320 | Y33: 0 | AA33: 43050.5 | AD33: =SUM(J33:AC33) -> 241257.24 | AE33: =AD33-SUM(J33:AC33) -> 0 | AF33: =AD33-I33 -> 0 | AG33: =ROUND(H33,2) -> 13656.07 | AH33: =ROUND(AG33*0.07,2) -> 955.92 | AI33: =ROUND(AG33*0.03,2) -> 409.68 | AJ33: =ROUND(AG33*0.02,2) -> 273.12 | AK33: =IF(AR33,Y33/(AR33*1.12)*AR33,0) -> 0 | AL33: =ROUND(Y33-AK33,2) -> 0 | AM33: =ROUND(AG33-AK33,2) -> 13656.07 | AN33: =ROUND(AM33*0.07,2) -> 955.92 | AO33: =ROUND(AM33*0.03,2) -> 409.68 | AP33: =ROUND(AH33+AI33+AJ33-AL33-AN33-AO33,2) -> 273.12 | AQ33: ="TJ"&A33 -> TJ202512031007000000620 | AR33: =IF(E33="无全额",0,MID(E33,4,2)*1) -> 0.06
A34: 202512031207000266938 | B34: 辉山乳业（沈阳）销售有限公司 | C34: 劳务承揽 | D34: 承揽业务 | E34: 专票（6%） | F34: =ROUND(SUMIF([1]开票!$A$2:$A$1750,[1]申请!AQ34,[1]开票!$C$2:$C$1750),2) -> 5473.52 | G34: =ROUND(SUMIF([1]开票!$A$2:$A$1750,[1]申请!AQ34,[1]开票!$D$2:$D$1750),2) -> 0 | H34: =ROUND(SUMIF([1]开票!$A$2:$A$1750,[1]申请!AQ34,[1]开票!$E$2:$E$1750),2) -> 328.41 | I34: =SUM(F34:H34) -> 5801.93 | L34: 5801.93 | AD34: =SUM(J34:AC34) -> 5801.93 | AE34: =AD34-SUM(J34:AC34) -> 0 | AF34: =AD34-I34 -> 0 | AG34: =ROUND(H34,2) -> 328.41 | AH34: =ROUND(AG34*0.07,2) -> 22.99 | AI34: =ROUND(AG34*0.03,2) -> 9.85 | AJ34: =ROUND(AG34*0.02,2) -> 6.57 | AK34: =IF(AR34,Y34/(AR34*1.12)*AR34,0) -> 0 | AL34: =ROUND(Y34-AK34,2) -> 0 | AM34: =ROUND(AG34-AK34,2) -> 328.41 | AN34: =ROUND(AM34*0.07,2) -> 22.99 | AO34: =ROUND(AM34*0.03,2) -> 9.85 | AP34: =ROUND(AH34+AI34+AJ34-AL34-AN34-AO34,2) -> 6.57 | AQ34: ="TJ"&A34 -> TJ202512031207000266938 | AR34: =IF(E34="无全额",0,MID(E34,4,2)*1) -> 0.06
A35: 202512031357000592545 | B35: 广州市第一中学 | C35: 劳务派遣 | D35: 派遣业务 | E35: 普票（5%） | F35: =ROUND(SUMIF([1]开票!$A$2:$A$1750,[1]申请!AQ35,[1]开票!$C$2:$C$1750),2) -> 0 | G35: =ROUND(SUMIF([1]开票!$A$2:$A$1750,[1]申请!AQ35,[1]开票!$D$2:$D$1750),2) -> 40870 | H35: =ROUND(SUMIF([1]开票!$A$2:$A$1750,[1]申请!AQ35,[1]开票!$E$2:$E$1750),2) -> 0 | I35: =SUM(F35:H35) -> 40870 | K35: 0 | S35: 40870 | T35: 0 | U35: 0 | V35: 0 | X35: 0 | AD35: =SUM(J35:AC35) -> 40870 | AE35: =AD35-SUM(J35:AC35) -> 0 | AF35: =AD35-I35 -> 0 | AG35: =ROUND(H35,2) -> 0 | AH35: =ROUND(AG35*0.07,2) -> 0 | AI35: =ROUND(AG35*0.03,2) -> 0 | AJ35: =ROUND(AG35*0.02,2) -> 0 | AK35: =IF(AR35,Y35/(AR35*1.12)*AR35,0) -> 0 | AL35: =ROUND(Y35-AK35,2) -> 0 | AM35: =ROUND(AG35-AK35,2) -> 0 | AN35: =ROUND(AM35*0.07,2) -> 0 | AO35: =ROUND(AM35*0.03,2) -> 0 | AP35: =ROUND(AH35+AI35+AJ35-AL35-AN35-AO35,2) -> 0 | AQ35: ="TJ"&A35 -> TJ202512031357000592545 | AR35: =IF(E35="无全额",0,MID(E35,4,2)*1) -> 0.05
A36: 202512031410000212031 | B36: 广州市第一中学 | C36: 劳务派遣 | D36: 派遣业务 | E36: 普票（5%） | F36: =ROUND(SUMIF([1]开票!$A$2:$A$1750,[1]申请!AQ36,[1]开票!$C$2:$C$1750),2) -> 2228.57 | G36: =ROUND(SUMIF([1]开票!$A$2:$A$1750,[1]申请!AQ36,[1]开票!$D$2:$D$1750),2) -> 263840.73 | H36: =ROUND(SUMIF([1]开票!$A$2:$A$1750,[1]申请!AQ36,[1]开票!$E$2:$E$1750),2) -> 111.43 | I36: =SUM(F36:H36) -> 266180.73 | K36: 2340 | S36: 169028.62 | T36: 262.85 | U36: 71919.66 | V36: 21042 | X36: 1587.6 | AD36: =SUM(J36:AC36) -> 266180.73 | AE36: =AD36-SUM(J36:AC36) -> 0 | AF36: =AD36-I36 -> 0 | AG36: =ROUND(H36,2) -> 111.43 | AH36: =ROUND(AG36*0.07,2) -> 7.8 | AI36: =ROUND(AG36*0.03,2) -> 3.34 | AJ36: =ROUND(AG36*0.02,2) -> 2.23 | AK36: =IF(AR36,Y36/(AR36*1.12)*AR36,0) -> 0 | AL36: =ROUND(Y36-AK36,2) -> 0 | AM36: =ROUND(AG36-AK36,2) -> 111.43 | AN36: =ROUND(AM36*0.07,2) -> 7.8 | AO36: =ROUND(AM36*0.03,2) -> 3.34 | AP36: =ROUND(AH36+AI36+AJ36-AL36-AN36-AO36,2) -> 2.23 | AQ36: ="TJ"&A36 -> TJ202512031410000212031 | AR36: =IF(E36="无全额",0,MID(E36,4,2)*1) -> 0.05
A37: 202512031411000228772 | B37: 广州市第一中学 | C37: 劳务派遣 | D37: 派遣业务 | E37: 专票（6%） | F37: =ROUND(SUMIF([1]开票!$A$2:$A$1750,[1]申请!AQ37,[1]开票!$C$2:$C$1750),2) -> 35.85 | G37: =ROUND(SUMIF([1]开票!$A$2:$A$1750,[1]申请!AQ37,[1]开票!$D$2:$D$1750),2) -> 0 | H37: =ROUND(SUMIF([1]开票!$A$2:$A$1750,[1]申请!AQ37,[1]开票!$E$2:$E$1750),2) -> 2.15 | I37: =SUM(F37:H37) -> 38 | P37: 11 | W37: 27 | AD37: =SUM(J37:AC37) -> 38 | AE37: =AD37-SUM(J37:AC37) -> 0 | AF37: =AD37-I37 -> 0 | AG37: =ROUND(H37,2) -> 2.15 | AH37: =ROUND(AG37*0.07,2) -> 0.15 | AI37: =ROUND(AG37*0.03,2) -> 0.06 | AJ37: =ROUND(AG37*0.02,2) -> 0.04 | AK37: =IF(AR37,Y37/(AR37*1.12)*AR37,0) -> 0 | AL37: =ROUND(Y37-AK37,2) -> 0 | AM37: =ROUND(AG37-AK37,2) -> 2.15 | AN37: =ROUND(AM37*0.07,2) -> 0.15 | AO37: =ROUND(AM37*0.03,2) -> 0.06 | AP37: =ROUND(AH37+AI37+AJ37-AL37-AN37-AO37,2) -> 0.04 | AQ37: ="TJ"&A37 -> TJ202512031411000228772 | AR37: =IF(E37="无全额",0,MID(E37,4,2)*1) -> 0.06
A38: 202512031527000358276 | B38: 蚂蚁HRO | C38: 劳务承揽 | D38: 承揽业务 | E38: 专票（6%） | F38: =ROUND(SUMIF([1]开票!$A$2:$A$1750,[1]申请!AQ38,[1]开票!$C$2:$C$1750),2) -> 14639.37 | G38: =ROUND(SUMIF([1]开票!$A$2:$A$1750,[1]申请!AQ38,[1]开票!$D$2:$D$1750),2) -> 0 | H38: =ROUND(SUMIF([1]开票!$A$2:$A$1750,[1]申请!AQ38,[1]开票!$E$2:$E$1750),2) -> 878.36 | I38: =SUM(F38:H38) -> 15517.73 | J38: 15517.73 | AD38: =SUM(J38:AC38) -> 15517.73 | AE38: =AD38-SUM(J38:AC38) -> 0 | AF38: =AD38-I38 -> 0 | AG38: =ROUND(H38,2) -> 878.36 | AH38: =ROUND(AG38*0.07,2) -> 61.49 | AI38: =ROUND(AG38*0.03,2) -> 26.35 | AJ38: =ROUND(AG38*0.02,2) -> 17.57 | AK38: =IF(AR38,Y38/(AR38*1.12)*AR38,0) -> 0 | AL38: =ROUND(Y38-AK38,2) -> 0 | AM38: =ROUND(AG38-AK38,2) -> 878.36 | AN38: =ROUND(AM38*0.07,2) -> 61.49 | AO38: =ROUND(AM38*0.03,2) -> 26.35 | AP38: =ROUND(AH38+AI38+AJ38-AL38-AN38-AO38,2) -> 17.57 | AQ38: ="TJ"&A38 -> TJ202512031527000358276 | AR38: =IF(E38="无全额",0,MID(E38,4,2)*1) -> 0.06
A39: 202512031546000048920 | B39: 广汽传祺汽车销售有限公司 | C39: 劳务承揽 | D39: 小时间承揽 | E39: 普票（6%） | F39: =ROUND(SUMIF([1]开票!$A$2:$A$1750,[1]申请!AQ39,[1]开票!$C$2:$C$1750),2) -> 801132.08 | G39: =ROUND(SUMIF([1]开票!$A$2:$A$1750,[1]申请!AQ39,[1]开票!$D$2:$D$1750),2) -> 0 | H39: =ROUND(SUMIF([1]开票!$A$2:$A$1750,[1]申请!AQ39,[1]开票!$E$2:$E$1750),2) -> 48067.92 | I39: =SUM(F39:H39) -> 849200 | L39: 48066.13 | S39: 801133.87 | AD39: =SUM(J39:AC39) -> 849200 | AE39: =AD39-SUM(J39:AC39) -> 0 | AF39: =AD39-I39 -> 0 | AG39: =ROUND(H39,2) -> 48067.92 | AH39: =ROUND(AG39*0.07,2) -> 3364.75 | AI39: =ROUND(AG39*0.03,2) -> 1442.04 | AJ39: =ROUND(AG39*0.02,2) -> 961.36 | AK39: =IF(AR39,Y39/(AR39*1.12)*AR39,0) -> 0 | AL39: =ROUND(Y39-AK39,2) -> 0 | AM39: =ROUND(AG39-AK39,2) -> 48067.92 | AN39: =ROUND(AM39*0.07,2) -> 3364.75 | AO39: =ROUND(AM39*0.03,2) -> 1442.04 | AP39: =ROUND(AH39+AI39+AJ39-AL39-AN39-AO39,2) -> 961.36 | AQ39: ="TJ"&A39 -> TJ202512031546000048920 | AR39: =IF(E39="无全额",0,MID(E39,4,2)*1) -> 0.06
A40: 202512031618000265075 | B40: 优湃能源科技（广州）有限公司 | C40: 劳务承揽 | D40: 承揽业务 | E40: 专票（6%） | F40: =ROUND(SUMIF([1]开票!$A$2:$A$1750,[1]申请!AQ40,[1]开票!$C$2:$C$1750),2) -> 350842.08 | G40: =ROUND(SUMIF([1]开票!$A$2:$A$1750,[1]申请!AQ40,[1]开票!$D$2:$D$1750),2) -> 0 | H40: =ROUND(SUMIF([1]开票!$A$2:$A$1750,[1]申请!AQ40,[1]开票!$E$2:$E$1750),2) -> 21050.52 | I40: =SUM(F40:H40) -> 371892.6 | L40: 371892.6 | AD40: =SUM(J40:AC40) -> 371892.6 | AE40: =AD40-SUM(J40:AC40) -> 0 | AF40: =AD40-I40 -> 0 | AG40: =ROUND(H40,2) -> 21050.52 | AH40: =ROUND(AG40*0.07,2) -> 1473.54 | AI40: =ROUND(AG40*0.03,2) -> 631.52 | AJ40: =ROUND(AG40*0.02,2) -> 421.01 | AK40: =IF(AR40,Y40/(AR40*1.12)*AR40,0) -> 0 | AL40: =ROUND(Y40-AK40,2) -> 0 | AM40: =ROUND(AG40-AK40,2) -> 21050.52 | AN40: =ROUND(AM40*0.07,2) -> 1473.54 | AO40: =ROUND(AM40*0.03,2) -> 631.52 | AP40: =ROUND(AH40+AI40+AJ40-AL40-AN40-AO40,2) -> 421.01 | AQ40: ="TJ"&A40 -> TJ202512031618000265075 | AR40: =IF(E40="无全额",0,MID(E40,4,2)*1) -> 0.06
...

Sheet Sheet2

Sheet Sheet3
